Workbook
Name Slicer_Category: #N/A
Name Slicer_Gender: #N/A
Name Slicer_Location: #N/A
Name Slicer_Season: #N/A
Name tblCombined: Table2[]

Sheet Customers
A1: Customer ID | B1: Customer name | C1: Age | D1: Location | E1: Gender
A2: C009 | B2: Linda Davis | C2: 53 | D2: Calabar | E2: Female
A3: C008 | B3: Rita Abubakar | C3: 27 | D3: Owerri | E3: Female
A4: C010 | B4: Grace Anderson | C4: 54 | D4: Abeokuta | E4: Female
A5: C139 | B5: Daniel White | C5: 20 | D5: Uyo | E5: Male
A6: C047 | B6: Tunde Jackson | C6: 52 | D6: Ilorin | E6: Male
A7: C060 | B7: Ifeoma Chukwu | C7: 58 | D7: Enugu | E7: Female
A8: C018 | B8: Tunde Uche | C8: 44 | D8: Lagos | E8: Male
A9: C091 | B9: James Balogun | C9: 41 | D9: Lagos | E9: Male
A10: C077 | B10: Laura Eze | C10: 20 | D10: Jos | E10: Female
A11: C114 | B11: Amara Johnson | C11: 58 | D11: Warri | E11: Female
A12: C051 | B12: John Okoro | C12: 30 | D12: Jos | E12: Male
A13: C118 | B13: Blessing Moore | C13: 18 | D13: Kano | E13: Female
... A144: C119 | B144: Peter Suleiman | C144: 38 | D144: Ibadan | E144: Male

Sheet Promo Codes
A1: Promo Code | B1: Discount
A2: WELCOME10 | B2: 0.1
A3: SEASON15 | B3: 0.15
A4: VIP20 | B4: 0.2
A5: FLASH5 | B5: 0.05

Sheet Products
A1: Product ID | B1: Category | C1: Product Name | D1: Price
A2: P01 | B2: Clothing | C2: Ankara Dress | D2: 68
A3: P02 | B3: Clothing | C3: Denim Jacket | D3: 95
A4: P03 | B4: Clothing | C4: Silk Blouse | D4: 54
A5: P04 | B5: Clothing | C5: Maxi Gown | D5: 120
A6: P05 | B6: Clothing | C6: Linen Trousers | D6: 47
A7: P06 | B7: Clothing | C7: Kaftan | D7: 89
A8: P07 | B8: Clothing | C8: Blazer | D8: 135
A9: P08 | B9: Clothing | C9: Jumpsuit | D9: 76
A10: P09 | B10: Clothing | C10: Wrap Skirt | D10: 42
A11: P10 | B11: Clothing | C11: Knit Sweater | D11: 58
A12: P11 | B12: Accessories | C12: Beaded Necklace | D12: 25
A13: P12 | B13: Accessories | C13: Leather Handbag | D13: 145
... A21: P20 | B21: Accessories | C21: Waist Belt | D21: 33

Sheet DashboardData
A1: Sum of Price | B1: Distinct Count of Customer ID | C1: Average of Price2 | H1: Sum of Price | I1: Column Labels
A2: 421 | B2: 4 | C2: 70.166667 | H2: Row Labels | I2: Accessories | J2: Clothing | K2: Grand Total
A3: ="$"&TEXT(A2,"#,##0") -> $421 | C3: ="$"&TEXT(C2,"0.00") -> $70.17 | H3: Fall | I3: 148 | K3: 148
A4: Row Labels | B4: Sum of Price | E4: Row Labels | F4: Sum of Price | H4: Spring | I4: 48 | K4: 48
A5: Male | B5: 421 | E5: Ilorin | F5: 421 | H5: Summer | J5: 177 | K5: 177
A6: Grand Total | B6: 421 | E6: Grand Total | F6: 421 | H6: Winter | I6: 48 | K6: 48
H7: Grand Total | I7: 244 | J7: 177 | K7: 421
A9: Row Labels | B9: Sum of Price
A10: 20-40 | B10: 48
A11: 40-60 | B11: 373 | I11: Count of Promo Code | J11: Percentage of promo code | L11: Row Labels | M11: Sum of Price
A12: Grand Total | B12: 421 | I12: 3 | J12: =GETPIVOTDATA("[Measures].[Count of Promo Code]",$I$11)/GETPIVOTDATA("[Measures].[Count of Order ID]",$B$16) -> 0.5 | L12: Accessories | M12: 244
L13: Clothing | M13: 177
L14: Grand Total | M14: 421
K15: =TEXT(J12,"0%") -> 50%
B16: Row Labels | C16: Count of Order ID
B17: Bank Transfer | C17: 4
B18: Debit Card | C18: 1 | J18: Row Labels | K18: Distinct Count of Customer ID
B19: PayPal | C19: 1 | J19: One-Time Customer | K19: 3
B20: Grand Total | C20: 6 | H20: Row Labels | I20: Count of Customer ID | J20: Repeat Customer | K20: 1
H21: No Code | I21: 3 | J21: Grand Total | K21: 4
H22: Used Code | I22: 3
H23: Grand Total | I23: 6

Sheet Dashboard

Sheet Combined Data
A1: Order ID | B1: Customer ID | C1: Product ID | D1: Order Date | E1: Payment Method | F1: Promo Code | G1: Customer Name | H1: Gender | I1: Age | J1: Location | K1: Category | L1: Product Name | M1: Price | N1: Season | O1: Age Group | P1: Repeat Customer | Q1: Promo Used
A2: 5012 | B2: C004 | C2: P10 | D2: 46266 | E2: Cash on Delivery | F2: WELCOME10 | G2: =INDEX(Customers!B:B,MATCH(B2,Customers!A:A,0)) -> Steven Johnson | H2: =INDEX(Customers!E:E,MATCH(B2,Customers!A:A,0)) -> Male | I2: =INDEX(Customers!C:C,MATCH(B2,Customers!A:A,0)) -> 33 | J2: =INDEX(Customers!D:D,MATCH(B2,Customers!A:A,0)) -> Abuja | K2: =INDEX(Products!B:B,MATCH(C2,Products!A:A,0)) -> Clothing | L2: =INDEX(Products!C:C,MATCH(C2,Products!A:A,0)) -> Knit Sweater | M2: =INDEX(Products!D:D,MATCH(C2,Products!A:A,0)) -> 58 | N2: =CHOOSE(MONTH(D2),"Winter","Winter","Spring","Spring","Spring","Summer","Summer","Summer","Fall","Fall","Fall","Winter") -> Fall | O2: =IF(I2<20,"<20",IF(I2<40,"20-40",IF(I2<60,"40-60","60+"))) -> 20-40 | P2: =IF(COUNTIF(B:B,B2)>1,"Yes","No") -> Yes | Q2: =IF(F2="","No Code","Used Code") -> Used Code
A3: 5033 | B3: C014 | C3: P15 | D3: 46085 | E3: Debit Card | G3: =INDEX(Customers!B:B,MATCH(B3,Customers!A:A,0)) -> Mark Davis | H3: =INDEX(Customers!E:E,MATCH(B3,Customers!A:A,0)) -> Male | I3: =INDEX(Customers!C:C,MATCH(B3,Customers!A:A,0)) -> 33 | J3: =INDEX(Customers!D:D,MATCH(B3,Customers!A:A,0)) -> Jos | K3: =INDEX(Products!B:B,MATCH(C3,Products!A:A,0)) -> Accessories | L3: =INDEX(Products!C:C,MATCH(C3,Products!A:A,0)) -> Tote Bag | M3: =INDEX(Products!D:D,MATCH(C3,Products!A:A,0)) -> 62 | N3: =CHOOSE(MONTH(D3),"Winter","Winter","Spring","Spring","Spring","Summer","Summer","Summer","Fall","Fall","Fall","Winter") -> Spring | O3: =IF(I3<20,"<20",IF(I3<40,"20-40",IF(I3<60,"40-60","60+"))) -> 20-40 | P3: =IF(COUNTIF(B:B,B3)>1,"Yes","No") -> Yes | Q3: =IF(F3="","No Code","Used Code") -> No Code
A4: 5117 | B4: C056 | C4: P20 | D4: 46045 | E4: PayPal | F4: VIP20 | G4: =INDEX(Customers!B:B,MATCH(B4,Customers!A:A,0)) -> Aisha Bello | H4: =INDEX(Customers!E:E,MATCH(B4,Customers!A:A,0)) -> Female | I4: =INDEX(Customers!C:C,MATCH(B4,Customers!A:A,0)) -> 32 | J4: =INDEX(Customers!D:D,MATCH(B4,Customers!A:A,0)) -> Kaduna | K4: =INDEX(Products!B:B,MATCH(C4,Products!A:A,0)) -> Accessories | L4: =INDEX(Products!C:C,MATCH(C4,Products!A:A,0)) -> Waist Belt | M4: =INDEX(Products!D:D,MATCH(C4,Products!A:A,0)) -> 33 | N4: =CHOOSE(MONTH(D4),"Winter","Winter","Spring","Spring","Spring","Summer","Summer","Summer","Fall","Fall","Fall","Winter") -> Winter | O4: =IF(I4<20,"<20",IF(I4<40,"20-40",IF(I4<60,"40-60","60+"))) -> 20-40 | P4: =IF(COUNTIF(B:B,B4)>1,"Yes","No") -> Yes | Q4: =IF(F4="","No Code","Used Code") -> Used Code
A5: 5201 | B5: C099 | C5: P19 | D5: 46041 | E5: Card | G5: =INDEX(Customers!B:B,MATCH(B5,Customers!A:A,0)) -> Ifeoma Martin | H5: =INDEX(Customers!E:E,MATCH(B5,Customers!A:A,0)) -> Female | I5: =INDEX(Customers!C:C,MATCH(B5,Customers!A:A,0)) -> 22 | J5: =INDEX(Customers!D:D,MATCH(B5,Customers!A:A,0)) -> Kano | K5: =INDEX(Products!B:B,MATCH(C5,Products!A:A,0)) -> Accessories | L5: =INDEX(Products!C:C,MATCH(C5,Products!A:A,0)) -> Earrings | M5: =INDEX(Products!D:D,MATCH(C5,Products!A:A,0)) -> 19 | N5: =CHOOSE(MONTH(D5),"Winter","Winter","Spring","Spring","Spring","Summer","Summer","Summer","Fall","Fall","Fall","Winter") -> Winter | O5: =IF(I5<20,"<20",IF(I5<40,"20-40",IF(I5<60,"40-60","60+"))) -> 20-40 | P5: =IF(COUNTIF(B:B,B5)>1,"Yes","No") -> Yes | Q5: =IF(F5="","No Code","Used Code") -> No Code
A6: 5270 | B6: C130 | C6: P03 | D6: 45990 | E6: Bank Transfer | F6: VIP20 | G6: =INDEX(Customers!B:B,MATCH(B6,Customers!A:A,0)) -> Linda Chukwu | H6: =INDEX(Customers!E:E,MATCH(B6,Customers!A:A,0)) -> Female | I6: =INDEX(Customers!C:C,MATCH(B6,Customers!A:A,0)) -> 59 | J6: =INDEX(Customers!D:D,MATCH(B6,Customers!A:A,0)) -> Ibadan | K6: =INDEX(Products!B:B,MATCH(C6,Products!A:A,0)) -> Clothing | L6: =INDEX(Products!C:C,MATCH(C6,Products!A:A,0)) -> Silk Blouse | M6: =INDEX(Products!D:D,MATCH(C6,Products!A:A,0)) -> 54 | N6: =CHOOSE(MONTH(D6),"Winter","Winter","Spring","Spring","Spring","Summer","Summer","Summer","Fall","Fall","Fall","Winter") -> Fall | O6: =IF(I6<20,"<20",IF(I6<40,"20-40",IF(I6<60,"40-60","60+"))) -> 40-60 | P6: =IF(COUNTIF(B:B,B6)>1,"Yes","No") -> Yes | Q6: =IF(F6="","No Code","Used Code") -> Used Code
A7: 5154 | B7: C076 | C7: P10 | D7: 46106 | E7: Cash on Delivery | F7: FLASH5 | G7: =INDEX(Customers!B:B,MATCH(B7,Customers!A:A,0)) -> Michael Martin | H7: =INDEX(Customers!E:E,MATCH(B7,Customers!A:A,0)) -> Male | I7: =INDEX(Customers!C:C,MATCH(B7,Customers!A:A,0)) -> 53 | J7: =INDEX(Customers!D:D,MATCH(B7,Customers!A:A,0)) -> Unknown | K7: =INDEX(Products!B:B,MATCH(C7,Products!A:A,0)) -> Clothing | L7: =INDEX(Products!C:C,MATCH(C7,Products!A:A,0)) -> Knit Sweater | M7: =INDEX(Products!D:D,MATCH(C7,Products!A:A,0)) -> 58 | N7: =CHOOSE(MONTH(D7),"Winter","Winter","Spring","Spring","Spring","Summer","Summer","Summer","Fall","Fall","Fall","Winter") -> Spring | O7: =IF(I7<20,"<20",IF(I7<40,"20-40",IF(I7<60,"40-60","60+"))) -> 40-60 | P7: =IF(COUNTIF(B:B,B7)>1,"Yes","No") -> Yes | Q7: =IF(F7="","No Code","Used Code") -> Used Code
A8: 5259 | B8: C126 | C8: P08 | D8: 46358 | E8: Card | G8: =INDEX(Customers!B:B,MATCH(B8,Customers!A:A,0)) -> Angela Wilson | H8: =INDEX(Customers!E:E,MATCH(B8,Customers!A:A,0)) -> Female | I8: =INDEX(Customers!C:C,MATCH(B8,Customers!A:A,0)) -> 38 | J8: =INDEX(Customers!D:D,MATCH(B8,Customers!A:A,0)) -> Warri | K8: =INDEX(Products!B:B,MATCH(C8,Products!A:A,0)) -> Clothing | L8: =INDEX(Products!C:C,MATCH(C8,Products!A:A,0)) -> Jumpsuit | M8: =INDEX(Products!D:D,MATCH(C8,Products!A:A,0)) -> 76 | N8: =CHOOSE(MONTH(D8),"Winter","Winter","Spring","Spring","Spring","Summer","Summer","Summer","Fall","Fall","Fall","Winter") -> Winter | O8: =IF(I8<20,"<20",IF(I8<40,"20-40",IF(I8<60,"40-60","60+"))) -> 20-40 | P8: =IF(COUNTIF(B:B,B8)>1,"Yes","No") -> No | Q8: =IF(F8="","No Code","Used Code") -> No Code
A9: 5198 | B9: C098 | C9: P06 | D9: 45842 | E9: PayPal | G9: =INDEX(Customers!B:B,MATCH(B9,Customers!A:A,0)) -> Peter Johnson | H9: =INDEX(Customers!E:E,MATCH(B9,Customers!A:A,0)) -> Male | I9: =INDEX(Customers!C:C,MATCH(B9,Customers!A:A,0)) -> 35 | J9: =INDEX(Customers!D:D,MATCH(B9,Customers!A:A,0)) -> Lagos | K9: =INDEX(Products!B:B,MATCH(C9,Products!A:A,0)) -> Clothing | L9: =INDEX(Products!C:C,MATCH(C9,Products!A:A,0)) -> Kaftan | M9: =INDEX(Products!D:D,MATCH(C9,Products!A:A,0)) -> 89 | N9: =CHOOSE(MONTH(D9),"Winter","Winter","Spring","Spring","Spring","Summer","Summer","Summer","Fall","Fall","Fall","Winter") -> Summer | O9: =IF(I9<20,"<20",IF(I9<40,"20-40",IF(I9<60,"40-60","60+"))) -> 20-40 | P9: =IF(COUNTIF(B:B,B9)>1,"Yes","No") -> Yes | Q9: =IF(F9="","No Code","Used Code") -> No Code
A10: 5039 | B10: C017 | C10: P03 | D10: 46115 | E10: PayPal | G10: =INDEX(Customers!B:B,MATCH(B10,Customers!A:A,0)) -> Grace Taylor | H10: =INDEX(Customers!E:E,MATCH(B10,Customers!A:A,0)) -> Female | I10: =INDEX(Customers!C:C,MATCH(B10,Customers!A:A,0)) -> 44 | J10: =INDEX(Customers!D:D,MATCH(B10,Customers!A:A,0)) -> Port Harcourt | K10: =INDEX(Products!B:B,MATCH(C10,Products!A:A,0)) -> Clothing | L10: =INDEX(Products!C:C,MATCH(C10,Products!A:A,0)) -> Silk Blouse | M10: =INDEX(Products!D:D,MATCH(C10,Products!A:A,0)) -> 54 | N10: =CHOOSE(MONTH(D10),"Winter","Winter","Spring","Spring","Spring","Summer","Summer","Summer","Fall","Fall","Fall","Winter") -> Spring | O10: =IF(I10<20,"<20",IF(I10<40,"20-40",IF(I10<60,"40-60","60+"))) -> 40-60 | P10: =IF(COUNTIF(B:B,B10)>1,"Yes","No") -> Yes | Q10: =IF(F10="","No Code","Used Code") -> No Code
A11: 5085 | B11: C040 | C11: P03 | D11: 45896 | E11: Cash on Delivery | F11: WELCOME10 | G11: =INDEX(Customers!B:B,MATCH(B11,Customers!A:A,0)) -> Nkechi Okoro | H11: =INDEX(Customers!E:E,MATCH(B11,Customers!A:A,0)) -> Female | I11: =INDEX(Customers!C:C,MATCH(B11,Customers!A:A,0)) -> 19 | J11: =INDEX(Customers!D:D,MATCH(B11,Customers!A:A,0)) -> Abuja | K11: =INDEX(Products!B:B,MATCH(C11,Products!A:A,0)) -> Clothing | L11: =INDEX(Products!C:C,MATCH(C11,Products!A:A,0)) -> Silk Blouse | M11: =INDEX(Products!D:D,MATCH(C11,Products!A:A,0)) -> 54 | N11: =CHOOSE(MONTH(D11),"Winter","Winter","Spring","Spring","Spring","Summer","Summer","Summer","Fall","Fall","Fall","Winter") -> Summer | O11: =IF(I11<20,"<20",IF(I11<40,"20-40",IF(I11<60,"40-60","60+"))) -> <20 | P11: =IF(COUNTIF(B:B,B11)>1,"Yes","No") -> Yes | Q11: =IF(F11="","No Code","Used Code") -> Used Code
A12: 5088 | B12: C042 | C12: P01 | D12: 45788 | E12: Card | F12: WELCOME10 | G12: =INDEX(Customers!B:B,MATCH(B12,Customers!A:A,0)) -> Mark Okoro | H12: =INDEX(Customers!E:E,MATCH(B12,Customers!A:A,0)) -> Male | I12: =INDEX(Customers!C:C,MATCH(B12,Customers!A:A,0)) -> 41 | J12: =INDEX(Customers!D:D,MATCH(B12,Customers!A:A,0)) -> Unknown | K12: =INDEX(Products!B:B,MATCH(C12,Products!A:A,0)) -> Clothing | L12: =INDEX(Products!C:C,MATCH(C12,Products!A:A,0)) -> Ankara Dress | M12: =INDEX(Products!D:D,MATCH(C12,Products!A:A,0)) -> 68 | N12: =CHOOSE(MONTH(D12),"Winter","Winter","Spring","Spring","Spring","Summer","Summer","Summer","Fall","Fall","Fall","Winter") -> Spring | O12: =IF(I12<20,"<20",IF(I12<40,"20-40",IF(I12<60,"40-60","60+"))) -> 40-60 | P12: =IF(COUNTIF(B:B,B12)>1,"Yes","No") -> No | Q12: =IF(F12="","No Code","Used Code") -> Used Code
A13: 5205 | B13: C101 | C13: P07 | D13: 46083 | E13: Cash on Delivery | G13: =INDEX(Customers!B:B,MATCH(B13,Customers!A:A,0)) -> Fatima Eze | H13: =INDEX(Customers!E:E,MATCH(B13,Customers!A:A,0)) -> Female | I13: =INDEX(Customers!C:C,MATCH(B13,Customers!A:A,0)) -> 25 | J13: =INDEX(Customers!D:D,MATCH(B13,Customers!A:A,0)) -> Kaduna | K13: =INDEX(Products!B:B,MATCH(C13,Products!A:A,0)) -> Clothing | L13: =INDEX(Products!C:C,MATCH(C13,Products!A:A,0)) -> Blazer | M13: =INDEX(Products!D:D,MATCH(C13,Products!A:A,0)) -> 135 | N13: =CHOOSE(MONTH(D13),"Winter","Winter","Spring","Spring","Spring","Summer","Summer","Summer","Fall","Fall","Fall","Winter") -> Spring | O13: =IF(I13<20,"<20",IF(I13<40,"20-40",IF(I13<60,"40-60","60+"))) -> 20-40 | P13: =IF(COUNTIF(B:B,B13)>1,"Yes","No") -> No | Q13: =IF(F13="","No Code","Used Code") -> No Code
A14: 5181 | B14: C091 | C14: P11 | D14: 46115 | E14: PayPal | G14: =INDEX(Customers!B:B,MATCH(B14,Customers!A:A,0)) -> James Balogun | H14: =INDEX(Customers!E:E,MATCH(B14,Customers!A:A,0)) -> Male | I14: =INDEX(Customers!C:C,MATCH(B14,Customers!A:A,0)) -> 41 | J14: =INDEX(Customers!D:D,MATCH(B14,Customers!A:A,0)) -> Lagos | K14: =INDEX(Products!B:B,MATCH(C14,Products!A:A,0)) -> Accessories | L14: =INDEX(Products!C:C,MATCH(C14,Products!A:A,0)) -> Beaded Necklace | M14: =INDEX(Products!D:D,MATCH(C14,Products!A:A,0)) -> 25 | N14: =CHOOSE(MONTH(D14),"Winter","Winter","Spring","Spring","Spring","Summer","Summer","Summer","Fall","Fall","Fall","Winter") -> Spring | O14: =IF(I14<20,"<20",IF(I14<40,"20-40",IF(I14<60,"40-60","60+"))) -> 40-60 | P14: =IF(COUNTIF(B:B,B14)>1,"Yes","No") -> No | Q14: =IF(F14="","No Code","Used Code") -> No Code
A15: 5292 | B15: C137 | C15: P06 | D15: 46035 | E15: Bank Transfer | G15: =INDEX(Customers!B:B,MATCH(B15,Customers!A:A,0)) -> John Balogun | H15: =INDEX(Customers!E:E,MATCH(B15,Customers!A:A,0)) -> Male | I15: =INDEX(Customers!C:C,MATCH(B15,Customers!A:A,0)) -> 31 | J15: =INDEX(Customers!D:D,MATCH(B15,Customers!A:A,0)) -> Ibadan | K15: =INDEX(Products!B:B,MATCH(C15,Products!A:A,0)) -> Clothing | L15: =INDEX(Products!C:C,MATCH(C15,Products!A:A,0)) -> Kaftan | M15: =INDEX(Products!D:D,MATCH(C15,Products!A:A,0)) -> 89 | N15: =CHOOSE(MONTH(D15),"Winter","Winter","Spring","Spring","Spring","Summer","Summer","Summer","Fall","Fall","Fall","Winter") -> Winter | O15: =IF(I15<20,"<20",IF(I15<40,"20-40",IF(I15<60,"40-60","60+"))) -> 20-40 | P15: =IF(COUNTIF(B:B,B15)>1,"Yes","No") -> No | Q15: =IF(F15="","No Code","Used Code") -> No Code
A16: 5296 | B16: C139 | C16: P17 | D16: 46162 | E16: Card | F16: WELCOME10 | G16: =INDEX(Customers!B:B,MATCH(B16,Customers!A:A,0)) -> Daniel White | H16: =INDEX(Customers!E:E,MATCH(B16,Customers!A:A,0)) -> Male | I16: =INDEX(Customers!C:C,MATCH(B16,Customers!A:A,0)) -> 20 | J16: =INDEX(Customers!D:D,MATCH(B16,Customers!A:A,0)) -> Uyo | K16: =INDEX(Products!B:B,MATCH(C16,Products!A:A,0)) -> Accessories | L16: =INDEX(Products!C:C,MATCH(C16,Products!A:A,0)) -> Ankle Boots | M16: =INDEX(Products!D:D,MATCH(C16,Products!A:A,0)) -> 110 | N16: =CHOOSE(MONTH(D16),"Winter","Winter","Spring","Spring","Spring","Summer","Summer","Summer","Fall","Fall","Fall","Winter") -> Spring | O16: =IF(I16<20,"<20",IF(I16<40,"20-40",IF(I16<60,"40-60","60+"))) -> 20-40 | P16: =IF(COUNTIF(B:B,B16)>1,"Yes","No") -> Yes | Q16: =IF(F16="","No Code","Used Code") -> Used Code
A17: 5243 | B17: C121 | C17: P17 | D17: 46128 | E17: Cash on Delivery | F17: VIP20 | G17: =INDEX(Customers!B:B,MATCH(B17,Customers!A:A,0)) -> Chioma Wilson | H17: =INDEX(Customers!E:E,MATCH(B17,Customers!A:A,0)) -> Female | I17: =INDEX(Customers!C:C,MATCH(B17,Customers!A:A,0)) -> 23 | J17: =INDEX(Customers!D:D,MATCH(B17,Customers!A:A,0)) -> Kaduna | K17: =INDEX(Products!B:B,MATCH(C17,Products!A:A,0)) -> Accessories | L17: =INDEX(Products!C:C,MATCH(C17,Products!A:A,0)) -> Ankle Boots | M17: =INDEX(Products!D:D,MATCH(C17,Products!A:A,0)) -> 110 | N17: =CHOOSE(MONTH(D17),"Winter","Winter","Spring","Spring","Spring","Summer","Summer","Summer","Fall","Fall","Fall","Winter") -> Spring | O17: =IF(I17<20,"<20",IF(I17<40,"20-40",IF(I17<60,"40-60","60+"))) -> 20-40 | P17: =IF(COUNTIF(B:B,B17)>1,"Yes","No") -> Yes | Q17: =IF(F17="","No Code","Used Code") -> Used Code
A18: 5175 | B18: C087 | C18: P14 | D18: 45982 | E18: PayPal | G18: =INDEX(Customers!B:B,MATCH(B18,Customers!A:A,0)) -> Tunde Eze | H18: =INDEX(Customers!E:E,MATCH(B18,Customers!A:A,0)) -> Male | I18: =INDEX(Customers!C:C,MATCH(B18,Customers!A:A,0)) -> 26 | J18: =INDEX(Customers!D:D,MATCH(B18,Customers!A:A,0)) -> Kaduna | K18: =INDEX(Products!B:B,MATCH(C18,Products!A:A,0)) -> Accessories | L18: =INDEX(Products!C:C,MATCH(C18,Products!A:A,0)) -> Hair Scarf | M18: =INDEX(Products!D:D,MATCH(C18,Products!A:A,0)) -> 15 | N18: =CHOOSE(MONTH(D18),"Winter","Winter","Spring","Spring","Spring","Summer","Summer","Summer","Fall","Fall","Fall","Winter") -> Fall | O18: =IF(I18<20,"<20",IF(I18<40,"20-40",IF(I18<60,"40-60","60+"))) -> 20-40 | P18: =IF(COUNTIF(B:B,B18)>1,"Yes","No") -> Yes | Q18: =IF(F18="","No Code","Used Code") -> No Code
A19: 5146 | B19: C071 | C19: P12 | D19: 46048 | E19: Cash on Delivery | F19: VIP20 | G19: =INDEX(Customers!B:B,MATCH(B19,Customers!A:A,0)) -> Musa Harris | H19: =INDEX(Customers!E:E,MATCH(B19,Customers!A:A,0)) -> Male | I19: =INDEX(Customers!C:C,MATCH(B19,Customers!A:A,0)) -> 51 | J19: =INDEX(Customers!D:D,MATCH(B19,Customers!A:A,0)) -> Benin City | K19: =INDEX(Products!B:B,MATCH(C19,Products!A:A,0)) -> Accessories | L19: =INDEX(Products!C:C,MATCH(C19,Products!A:A,0)) -> Leather Handbag | M19: =INDEX(Products!D:D,MATCH(C19,Products!A:A,0)) -> 145 | N19: =CHOOSE(MONTH(D19),"Winter","Winter","Spring","Spring","Spring","Summer","Summer","Summer","Fall","Fall","Fall","Winter") -> Winter | O19: =IF(I19<20,"<20",IF(I19<40,"20-40",IF(I19<60,"40-60","60+"))) -> 40-60 | P19: =IF(COUNTIF(B:B,B19)>1,"Yes","No") -> No | Q19: =IF(F19="","No Code","Used Code") -> Used Code
A20: 5268 | B20: C130 | C20: P07 | D20: 45983 | E20: Bank Transfer | F20: VIP20 | G20: =INDEX(Customers!B:B,MATCH(B20,Customers!A:A,0)) -> Linda Chukwu | H20: =INDEX(Customers!E:E,MATCH(B20,Customers!A:A,0)) -> Female | I20: =INDEX(Customers!C:C,MATCH(B20,Customers!A:A,0)) -> 59 | J20: =INDEX(Customers!D:D,MATCH(B20,Customers!A:A,0)) -> Ibadan | K20: =INDEX(Products!B:B,MATCH(C20,Products!A:A,0)) -> Clothing | L20: =INDEX(Products!C:C,MATCH(C20,Products!A:A,0)) -> Blazer | M20: =INDEX(Products!D:D,MATCH(C20,Products!A:A,0)) -> 135 | N20: =CHOOSE(MONTH(D20),"Winter","Winter","Spring","Spring","Spring","Summer","Summer","Summer","Fall","Fall","Fall","Winter") -> Fall | O20: =IF(I20<20,"<20",IF(I20<40,"20-40",IF(I20<60,"40-60","60+"))) -> 40-60 | P20: =IF(COUNTIF(B:B,B20)>1,"Yes","No") -> Yes | Q20: =IF(F20="","No Code","Used Code") -> Used Code
A21: 5206 | B21: C102 | C21: P18 | D21: 46148 | E21: Card | F21: WELCOME10 | G21: =INDEX(Customers!B:B,MATCH(B21,Customers!A:A,0)) -> Chioma Suleiman | H21: =INDEX(Customers!E:E,MATCH(B21,Customers!A:A,0)) -> Female | I21: =INDEX(Customers!C:C,MATCH(B21,Customers!A:A,0)) -> 44 | J21: =INDEX(Customers!D:D,MATCH(B21,Customers!A:A,0)) -> Ilorin | K21: =INDEX(Products!B:B,MATCH(C21,Products!A:A,0)) -> Accessories | L21: =INDEX(Products!C:C,MATCH(C21,Products!A:A,0)) -> Clutch Purse | M21: =INDEX(Products!D:D,MATCH(C21,Products!A:A,0)) -> 48 | N21: =CHOOSE(MONTH(D21),"Winter","Winter","Spring","Spring","Spring","Summer","Summer","Summer","Fall","Fall","Fall","Winter") -> Spring | O21: =IF(I21<20,"<20",IF(I21<40,"20-40",IF(I21<60,"40-60","60+"))) -> 40-60 | P21: =IF(COUNTIF(B:B,B21)>1,"Yes","No") -> No | Q21: =IF(F21="","No Code","Used Code") -> Used Code
A22: 5054 | B22: C023 | C22: P09 | D22: 45898 | E22: Bank Transfer | G22: =INDEX(Customers!B:B,MATCH(B22,Customers!A:A,0)) -> Daniel Jackson | H22: =INDEX(Customers!E:E,MATCH(B22,Customers!A:A,0)) -> Male | I22: =INDEX(Customers!C:C,MATCH(B22,Customers!A:A,0)) -> 42 | J22: =INDEX(Customers!D:D,MATCH(B22,Customers!A:A,0)) -> Ilorin | K22: =INDEX(Products!B:B,MATCH(C22,Products!A:A,0)) -> Clothing | L22: =INDEX(Products!C:C,MATCH(C22,Products!A:A,0)) -> Wrap Skirt | M22: =INDEX(Products!D:D,MATCH(C22,Products!A:A,0)) -> 42 | N22: =CHOOSE(MONTH(D22),"Winter","Winter","Spring","Spring","Spring","Summer","Summer","Summer","Fall","Fall","Fall","Winter") -> Summer | O22: =IF(I22<20,"<20",IF(I22<40,"20-40",IF(I22<60,"40-60","60+"))) -> 40-60 | P22: =IF(COUNTIF(B:B,B22)>1,"Yes","No") -> Yes | Q22: =IF(F22="","No Code","Used Code") -> No Code
A23: 5171 | B23: C085 | C23: P19 | D23: 45889 | E23: PayPal | G23: =INDEX(Customers!B:B,MATCH(B23,Customers!A:A,0)) -> James Brown | H23: =INDEX(Customers!E:E,MATCH(B23,Customers!A:A,0)) -> Male | I23: =INDEX(Customers!C:C,MATCH(B23,Customers!A:A,0)) -> 60 | J23: =INDEX(Customers!D:D,MATCH(B23,Customers!A:A,0)) -> Kano | K23: =INDEX(Products!B:B,MATCH(C23,Products!A:A,0)) -> Accessories | L23: =INDEX(Products!C:C,MATCH(C23,Products!A:A,0)) -> Earrings | M23: =INDEX(Products!D:D,MATCH(C23,Products!A:A,0)) -> 19 | N23: =CHOOSE(MONTH(D23),"Winter","Winter","Spring","Spring","Spring","Summer","Summer","Summer","Fall","Fall","Fall","Winter") -> Summer | O23: =IF(I23<20,"<20",IF(I23<40,"20-40",IF(I23<60,"40-60","60+"))) -> 60+ | P23: =IF(COUNTIF(B:B,B23)>1,"Yes","No") -> No | Q23: =IF(F23="","No Code","Used Code") -> No Code
A24: 5250 | B24: C122 | C24: P12 | D24: 46164 | E24: Bank Transfer | F24: FLASH5 | G24: =INDEX(Customers!B:B,MATCH(B24,Customers!A:A,0)) -> Yusuf Thomas | H24: =INDEX(Customers!E:E,MATCH(B24,Customers!A:A,0)) -> Male | I24: =INDEX(Customers!C:C,MATCH(B24,Customers!A:A,0)) -> 30 | J24: =INDEX(Customers!D:D,MATCH(B24,Customers!A:A,0)) -> Ibadan | K24: =INDEX(Products!B:B,MATCH(C24,Products!A:A,0)) -> Accessories | L24: =INDEX(Products!C:C,MATCH(C24,Products!A:A,0)) -> Leather Handbag | M24: =INDEX(Products!D:D,MATCH(C24,Products!A:A,0)) -> 145 | N24: =CHOOSE(MONTH(D24),"Winter","Winter","Spring","Spring","Spring","Summer","Summer","Summer","Fall","Fall","Fall","Winter") -> Spring | O24: =IF(I24<20,"<20",IF(I24<40,"20-40",IF(I24<60,"40-60","60+"))) -> 20-40 | P24: =IF(COUNTIF(B:B,B24)>1,"Yes","No") -> Yes | Q24: =IF(F24="","No Code","Used Code") -> Used Code
A25: 5246 | B25: C121 | C25: P02 | D25: 45975 | E25: PayPal | F25: VIP20 | G25: =INDEX(Customers!B:B,MATCH(B25,Customers!A:A,0)) -> Chioma Wilson | H25: =INDEX(Customers!E:E,MATCH(B25,Customers!A:A,0)) -> Female | I25: =INDEX(Customers!C:C,MATCH(B25,Customers!A:A,0)) -> 23 | J25: =INDEX(Customers!D:D,MATCH(B25,Customers!A:A,0)) -> Kaduna | K25: =INDEX(Products!B:B,MATCH(C25,Products!A:A,0)) -> Clothing | L25: =INDEX(Products!C:C,MATCH(C25,Products!A:A,0)) -> Denim Jacket | M25: =INDEX(Products!D:D,MATCH(C25,Products!A:A,0)) -> 95 | N25: =CHOOSE(MONTH(D25),"Winter","Winter","Spring","Spring","Spring","Summer","Summer","Summer","Fall","Fall","Fall","Winter") -> Fall | O25: =IF(I25<20,"<20",IF(I25<40,"20-40",IF(I25<60,"40-60","60+"))) -> 20-40 | P25: =IF(COUNTIF(B:B,B25)>1,"Yes","No") -> Yes | Q25: =IF(F25="","No Code","Used Code") -> Used Code
A26: 5249 | B26: C122 | C26: P07 | D26: 46073 | E26: Card | F26: SEASON15 | G26: =INDEX(Customers!B:B,MATCH(B26,Customers!A:A,0)) -> Yusuf Thomas | H26: =INDEX(Customers!E:E,MATCH(B26,Customers!A:A,0)) -> Male | I26: =INDEX(Customers!C:C,MATCH(B26,Customers!A:A,0)) -> 30 | J26: =INDEX(Customers!D:D,MATCH(B26,Customers!A:A,0)) -> Ibadan | K26: =INDEX(Products!B:B,MATCH(C26,Products!A:A,0)) -> Clothing | L26: =INDEX(Products!C:C,MATCH(C26,Products!A:A,0)) -> Blazer | M26: =INDEX(Products!D:D,MATCH(C26,Products!A:A,0)) -> 135 | N26: =CHOOSE(MONTH(D26),"Winter","Winter","Spring","Spring","Spring","Summer","Summer","Summer","Fall","Fall","Fall","Winter") -> Winter | O26: =IF(I26<20,"<20",IF(I26<40,"20-40",IF(I26<60,"40-60","60+"))) -> 20-40 | P26: =IF(COUNTIF(B:B,B26)>1,"Yes","No") -> Yes | Q26: =IF(F26="","No Code","Used Code") -> Used Code
A27: 5014 | B27: C006 | C27: P05 | D27: 46109 | E27: Card | F27: FLASH5 | G27: =INDEX(Customers!B:B,MATCH(B27,Customers!A:A,0)) -> Linda Smith | H27: =INDEX(Customers!E:E,MATCH(B27,Customers!A:A,0)) -> Female | I27: =INDEX(Customers!C:C,MATCH(B27,Customers!A:A,0)) -> 54 | J27: =INDEX(Customers!D:D,MATCH(B27,Customers!A:A,0)) -> Uyo | K27: =INDEX(Products!B:B,MATCH(C27,Products!A:A,0)) -> Clothing | L27: =INDEX(Products!C:C,MATCH(C27,Products!A:A,0)) -> Linen Trousers | M27: =INDEX(Products!D:D,MATCH(C27,Products!A:A,0)) -> 47 | N27: =CHOOSE(MONTH(D27),"Winter","Winter","Spring","Spring","Spring","Summer","Summer","Summer","Fall","Fall","Fall","Winter") -> Spring | O27: =IF(I27<20,"<20",IF(I27<40,"20-40",IF(I27<60,"40-60","60+"))) -> 40-60 | P27: =IF(COUNTIF(B:B,B27)>1,"Yes","No") -> Yes | Q27: =IF(F27="","No Code","Used Code") -> Used Code
A28: 5179 | B28: C089 | C28: P03 | D28: 45948 | E28: Bank Transfer | F28: WELCOME10 | G28: =INDEX(Customers!B:B,MATCH(B28,Customers!A:A,0)) -> Sarah Jackson | H28: =INDEX(Customers!E:E,MATCH(B28,Customers!A:A,0)) -> Female | I28: =INDEX(Customers!C:C,MATCH(B28,Customers!A:A,0)) -> 45 | J28: =INDEX(Customers!D:D,MATCH(B28,Customers!A:A,0)) -> Unknown | K28: =INDEX(Products!B:B,MATCH(C28,Products!A:A,0)) -> Clothing | L28: =INDEX(Products!C:C,MATCH(C28,Products!A:A,0)) -> Silk Blouse | M28: =INDEX(Products!D:D,MATCH(C28,Products!A:A,0)) -> 54 | N28: =CHOOSE(MONTH(D28),"Winter","Winter","Spring","Spring","Spring","Summer","Summer","Summer","Fall","Fall","Fall","Winter") -> Fall | O28: =IF(I28<20,"<20",IF(I28<40,"20-40",IF(I28<60,"40-60","60+"))) -> 40-60 | P28: =IF(COUNTIF(B:B,B28)>1,"Yes","No") -> Yes | Q28: =IF(F28="","No Code","Used Code") -> Used Code
A29: 5102 | B29: C050 | C29: P19 | D29: 45997 | E29: Bank Transfer | G29: =INDEX(Customers!B:B,MATCH(B29,Customers!A:A,0)) -> Nkechi White | H29: =INDEX(Customers!E:E,MATCH(B29,Customers!A:A,0)) -> Female | I29: =INDEX(Customers!C:C,MATCH(B29,Customers!A:A,0)) -> 32 | J29: =INDEX(Customers!D:D,MATCH(B29,Customers!A:A,0)) -> Owerri | K29: =INDEX(Products!B:B,MATCH(C29,Products!A:A,0)) -> Accessories | L29: =INDEX(Products!C:C,MATCH(C29,Products!A:A,0)) -> Earrings | M29: =INDEX(Products!D:D,MATCH(C29,Products!A:A,0)) -> 19 | N29: =CHOOSE(MONTH(D29),"Winter","Winter","Spring","Spring","Spring","Summer","Summer","Summer","Fall","Fall","Fall","Winter") -> Winter | O29: =IF(I29<20,"<20",IF(I29<40,"20-40",IF(I29<60,"40-60","60+"))) -> 20-40 | P29: =IF(COUNTIF(B:B,B29)>1,"Yes","No") -> Yes | Q29: =IF(F29="","No Code","Used Code") -> No Code
A30: 5090 | B30: C043 | C30: P04 | D30: 45847 | E30: Bank Transfer | G30: =INDEX(Customers!B:B,MATCH(B30,Customers!A:A,0)) -> Grace Aliyu | H30: =INDEX(Customers!E:E,MATCH(B30,Customers!A:A,0)) -> Female | I30: =INDEX(Customers!C:C,MATCH(B30,Customers!A:A,0)) -> 49 | J30: =INDEX(Customers!D:D,MATCH(B30,Customers!A:A,0)) -> Kaduna | K30: =INDEX(Products!B:B,MATCH(C30,Products!A:A,0)) -> Clothing | L30: =INDEX(Products!C:C,MATCH(C30,Products!A:A,0)) -> Maxi Gown | M30: =INDEX(Products!D:D,MATCH(C30,Products!A:A,0)) -> 120 | N30: =CHOOSE(MONTH(D30),"Winter","Winter","Spring","Spring","Spring","Summer","Summer","Summer","Fall","Fall","Fall","Winter") -> Summer | O30: =IF(I30<20,"<20",IF(I30<40,"20-40",IF(I30<60,"40-60","60+"))) -> 40-60 | P30: =IF(COUNTIF(B:B,B30)>1,"Yes","No") -> Yes | Q30: =IF(F30="","No Code","Used Code") -> No Code
A31: 5136 | B31: C065 | C31: P05 | D31: 46066 | E31: Debit Card | F31: FLASH5 | G31: =INDEX(Customers!B:B,MATCH(B31,Customers!A:A,0)) -> Tunde Suleiman | H31: =INDEX(Customers!E:E,MATCH(B31,Customers!A:A,0)) -> Male | I31: =INDEX(Customers!C:C,MATCH(B31,Customers!A:A,0)) -> 53 | J31: =INDEX(Customers!D:D,MATCH(B31,Customers!A:A,0)) -> Port Harcourt | K31: =INDEX(Products!B:B,MATCH(C31,Products!A:A,0)) -> Clothing | L31: =INDEX(Products!C:C,MATCH(C31,Products!A:A,0)) -> Linen Trousers | M31: =INDEX(Products!D:D,MATCH(C31,Products!A:A,0)) -> 47 | N31: =CHOOSE(MONTH(D31),"Winter","Winter","Spring","Spring","Spring","Summer","Summer","Summer","Fall","Fall","Fall","Winter") -> Winter | O31: =IF(I31<20,"<20",IF(I31<40,"20-40",IF(I31<60,"40-60","60+"))) -> 40-60 | P31: =IF(COUNTIF(B:B,B31)>1,"Yes","No") -> Yes | Q31: =IF(F31="","No Code","Used Code") -> Used Code
A32: 5127 | B32: C059 | C32: P07 | D32: 45881 | E32: Card | G32: =INDEX(Customers!B:B,MATCH(B32,Customers!A:A,0)) -> Grace Wilson | H32: =INDEX(Customers!E:E,MATCH(B32,Customers!A:A,0)) -> Female | I32: =INDEX(Customers!C:C,MATCH(B32,Customers!A:A,0)) -> 30 | J32: =INDEX(Customers!D:D,MATCH(B32,Customers!A:A,0)) -> Kaduna | K32: =INDEX(Products!B:B,MATCH(C32,Products!A:A,0)) -> Clothing | L32: =INDEX(Products!C:C,MATCH(C32,Products!A:A,0)) -> Blazer | M32: =INDEX(Products!D:D,MATCH(C32,Products!A:A,0)) -> 135 | N32: =CHOOSE(MONTH(D32),"Winter","Winter","Spring","Spring","Spring","Summer","Summer","Summer","Fall","Fall","Fall","Winter") -> Summer | O32: =IF(I32<20,"<20",IF(I32<40,"20-40",IF(I32<60,"40-60","60+"))) -> 20-40 | P32: =IF(COUNTIF(B:B,B32)>1,"Yes","No") -> Yes | Q32: =IF(F32="","No Code","Used Code") -> No Code
A33: 5185 | B33: C093 | C33: P13 | D33: 45990 | E33: Debit Card | G33: =INDEX(Customers!B:B,MATCH(B33,Customers!A:A,0)) -> Halima Miller | H33: =INDEX(Customers!E:E,MATCH(B33,Customers!A:A,0)) -> Female | I33: =INDEX(Customers!C:C,MATCH(B33,Customers!A:A,0)) -> 51 | J33: =INDEX(Customers!D:D,MATCH(B33,Customers!A:A,0)) -> Uyo | K33: =INDEX(Products!B:B,MATCH(C33,Products!A:A,0)) -> Accessories | L33: =INDEX(Products!C:C,MATCH(C33,Products!A:A,0)) -> Sunglasses | M33: =INDEX(Products!D:D,MATCH(C33,Products!A:A,0)) -> 38 | N33: =CHOOSE(MONTH(D33),"Winter","Winter","Spring","Spring","Spring","Summer","Summer","Summer","Fall","Fall","Fall","Winter") -> Fall | O33: =IF(I33<20,"<20",IF(I33<40,"20-40",IF(I33<60,"40-60","60+"))) -> 40-60 | P33: =IF(COUNTIF(B:B,B33)>1,"Yes","No") -> No | Q33: =IF(F33="","No Code","Used Code") -> No Code
A34: 5103 | B34: C051 | C34: P03 | D34: 46086 | E34: Cash on Delivery | F34: SEASON15 | G34: =INDEX(Customers!B:B,MATCH(B34,Customers!A:A,0)) -> John Okoro | H34: =INDEX(Customers!E:E,MATCH(B34,Customers!A:A,0)) -> Male | I34: =INDEX(Customers!C:C,MATCH(B34,Customers!A:A,0)) -> 30 | J34: =INDEX(Customers!D:D,MATCH(B34,Customers!A:A,0)) -> Jos | K34: =INDEX(Products!B:B,MATCH(C34,Products!A:A,0)) -> Clothing | L34: =INDEX(Products!C:C,MATCH(C34,Products!A:A,0)) -> Silk Blouse | M34: =INDEX(Products!D:D,MATCH(C34,Products!A:A,0)) -> 54 | N34: =CHOOSE(MONTH(D34),"Winter","Winter","Spring","Spring","Spring","Summer","Summer","Summer","Fall","Fall","Fall","Winter") -> Spring | O34: =IF(I34<20,"<20",IF(I34<40,"20-40",IF(I34<60,"40-60","60+"))) -> 20-40 | P34: =IF(COUNTIF(B:B,B34)>1,"Yes","No") -> Yes | Q34: =IF(F34="","No Code","Used Code") -> Used Code
A35: 5133 | B35: C062 | C35: P12 | D35: 46080 | E35: Bank Transfer | F35: WELCOME10 | G35: =INDEX(Customers!B:B,MATCH(B35,Customers!A:A,0)) -> Sarah Williams | H35: =INDEX(Customers!E:E,MATCH(B35,Customers!A:A,0)) -> Female | I35: =INDEX(Customers!C:C,MATCH(B35,Customers!A:A,0)) -> 26 | J35: =INDEX(Customers!D:D,MATCH(B35,Customers!A:A,0)) -> Lagos | K35: =INDEX(Products!B:B,MATCH(C35,Products!A:A,0)) -> Accessories | L35: =INDEX(Products!C:C,MATCH(C35,Products!A:A,0)) -> Leather Handbag | M35: =INDEX(Products!D:D,MATCH(C35,Products!A:A,0)) -> 145 | N35: =CHOOSE(MONTH(D35),"Winter","Winter","Spring","Spring","Spring","Summer","Summer","Summer","Fall","Fall","Fall","Winter") -> Winter | O35: =IF(I35<20,"<20",IF(I35<40,"20-40",IF(I35<60,"40-60","60+"))) -> 20-40 | P35: =IF(COUNTIF(B:B,B35)>1,"Yes","No") -> Yes | Q35: =IF(F35="","No Code","Used Code") -> Used Code
A36: 5078 | B36: C036 | C36: P09 | D36: 46127 | E36: Debit Card | G36: =INDEX(Customers!B:B,MATCH(B36,Customers!A:A,0)) -> Kevin Wilson | H36: =INDEX(Customers!E:E,MATCH(B36,Customers!A:A,0)) -> Male | I36: =INDEX(Customers!C:C,MATCH(B36,Customers!A:A,0)) -> 24 | J36: =INDEX(Customers!D:D,MATCH(B36,Customers!A:A,0)) -> Kaduna | K36: =INDEX(Products!B:B,MATCH(C36,Products!A:A,0)) -> Clothing | L36: =INDEX(Products!C:C,MATCH(C36,Products!A:A,0)) -> Wrap Skirt | M36: =INDEX(Products!D:D,MATCH(C36,Products!A:A,0)) -> 42 | N36: =CHOOSE(MONTH(D36),"Winter","Winter","Spring","Spring","Spring","Summer","Summer","Summer","Fall","Fall","Fall","Winter") -> Spring | O36: =IF(I36<20,"<20",IF(I36<40,"20-40",IF(I36<60,"40-60","60+"))) -> 20-40 | P36: =IF(COUNTIF(B:B,B36)>1,"Yes","No") -> Yes | Q36: =IF(F36="","No Code","Used Code") -> No Code
A37: 5289 | B37: C136 | C37: P01 | D37: 45849 | E37: Card | F37: SEASON15 | G37: =INDEX(Customers!B:B,MATCH(B37,Customers!A:A,0)) -> Adaeze Eze | H37: =INDEX(Customers!E:E,MATCH(B37,Customers!A:A,0)) -> Female | I37: =INDEX(Customers!C:C,MATCH(B37,Customers!A:A,0)) -> 22 | J37: =INDEX(Customers!D:D,MATCH(B37,Customers!A:A,0)) -> Calabar | K37: =INDEX(Products!B:B,MATCH(C37,Products!A:A,0)) -> Clothing | L37: =INDEX(Products!C:C,MATCH(C37,Products!A:A,0)) -> Ankara Dress | M37: =INDEX(Products!D:D,MATCH(C37,Products!A:A,0)) -> 68 | N37: =CHOOSE(MONTH(D37),"Winter","Winter","Spring","Spring","Spring","Summer","Summer","Summer","Fall","Fall","Fall","Winter") -> Summer | O37: =IF(I37<20,"<20",IF(I37<40,"20-40",IF(I37<60,"40-60","60+"))) -> 20-40 | P37: =IF(COUNTIF(B:B,B37)>1,"Yes","No") -> Yes | Q37: =IF(F37="","No Code","Used Code") -> Used Code
A38: 5261 | B38: C127 | C38: P20 | D38: 45918 | E38: Bank Transfer | F38: WELCOME10 | G38: =INDEX(Customers!B:B,MATCH(B38,Customers!A:A,0)) -> Tunde Davis | H38: =INDEX(Customers!E:E,MATCH(B38,Customers!A:A,0)) -> Male | I38: =INDEX(Customers!C:C,MATCH(B38,Customers!A:A,0)) -> 57 | J38: =INDEX(Customers!D:D,MATCH(B38,Customers!A:A,0)) -> Abeokuta | K38: =INDEX(Products!B:B,MATCH(C38,Products!A:A,0)) -> Accessories | L38: =INDEX(Products!C:C,MATCH(C38,Products!A:A,0)) -> Waist Belt | M38: =INDEX(Products!D:D,MATCH(C38,Products!A:A,0)) -> 33 | N38: =CHOOSE(MONTH(D38),"Winter","Winter","Spring","Spring","Spring","Summer","Summer","Summer","Fall","Fall","Fall","Winter") -> Fall | O38: =IF(I38<20,"<20",IF(I38<40,"20-40",IF(I38<60,"40-60","60+"))) -> 40-60 | P38: =IF(COUNTIF(B:B,B38)>1,"Yes","No") -> Yes | Q38: =IF(F38="","No Code","Used Code") -> Used Code
A39: 5079 | B39: C036 | C39: P10 | D39: 45989 | E39: PayPal | G39: =INDEX(Customers!B:B,MATCH(B39,Customers!A:A,0)) -> Kevin Wilson | H39: =INDEX(Customers!E:E,MATCH(B39,Customers!A:A,0)) -> Male | I39: =INDEX(Customers!C:C,MATCH(B39,Customers!A:A,0)) -> 24 | J39: =INDEX(Customers!D:D,MATCH(B39,Customers!A:A,0)) -> Kaduna | K39: =INDEX(Products!B:B,MATCH(C39,Products!A:A,0)) -> Clothing | L39: =INDEX(Products!C:C,MATCH(C39,Products!A:A,0)) -> Knit Sweater | M39: =INDEX(Products!D:D,MATCH(C39,Products!A:A,0)) -> 58 | N39: =CHOOSE(MONTH(D39),"Winter","Winter","Spring","Spring","Spring","Summer","Summer","Summer","Fall","Fall","Fall","Winter") -> Fall | O39: =IF(I39<20,"<20",IF(I39<40,"20-40",IF(I39<60,"40-60","60+"))) -> 20-40 | P39: =IF(COUNTIF(B:B,B39)>1,"Yes","No") -> Yes | Q39: =IF(F39="","No Code","Used Code") -> No Code
A40: 5163 | B40: C080 | C40: P16 | D40: 45825 | E40: Cash on Delivery | G40: =INDEX(Customers!B:B,MATCH(B40,Customers!A:A,0)) -> Blessing Moore | H40: =INDEX(Customers!E:E,MATCH(B40,Customers!A:A,0)) -> Female | I40: =INDEX(Customers!C:C,MATCH(B40,Customers!A:A,0)) -> 50 | J40: =INDEX(Customers!D:D,MATCH(B40,Customers!A:A,0)) -> Owerri | K40: =INDEX(Products!B:B,MATCH(C40,Products!A:A,0)) -> Accessories | L40: =INDEX(Products!C:C,MATCH(C40,Products!A:A,0)) -> Bangle Set | M40: =INDEX(Products!D:D,MATCH(C40,Products!A:A,0)) -> 22 | N40: =CHOOSE(MONTH(D40),"Winter","Winter","Spring","Spring","Spring","Summer","Summer","Summer","Fall","Fall","Fall","Winter") -> Summer | O40: =IF(I40<20,"<20",IF(I40<40,"20-40",IF(I40<60,"40-60","60+"))) -> 40-60 | P40: =IF(COUNTIF(B:B,B40)>1,"Yes","No") -> Yes | Q40: =IF(F40="","No Code","Used Code") -> No Code
...
